Workbook

Sheet Досмотр по неделям
A1: Неделя к неделе: последняя заполненная против предыдущей
A2: Показатель | B2: =IF(Служебный!$K$2<2,"-","Неделя "&(Служебный!$K$2-1)&": "&TEXT(DAY(INDEX('Досмотр по неделям'!$B$73:$B$98,Служебный!$K$2-1)),"00")&"."&TEXT(MONTH(INDEX('Досмотр по неделям'!$B$73:$B$98,Служебный!$K$2-1)),"00")&" - "&TEXT(DAY(INDEX('Досмотр по неделям'!$C$73:$C$98,Служебный!$K$2-1)),"00")&"."&TEXT(MONTH(INDEX('Досмотр по неделям'!$C$73:$C$98,Служебный!$K$2-1)),"00")) -> Неделя 7: 17.08 - 23.08 | D2: =IF(Служебный!$K$2<1,"-","Неделя "&(Служебный!$K$2-0)&": "&TEXT(DAY(INDEX('Досмотр по неделям'!$B$73:$B$98,Служебный!$K$2-0)),"00")&"."&TEXT(MONTH(INDEX('Досмотр по неделям'!$B$73:$B$98,Служебный!$K$2-0)),"00")&" - "&TEXT(DAY(INDEX('Досмотр по неделям'!$C$73:$C$98,Служебный!$K$2-0)),"00")&"."&TEXT(MONTH(INDEX('Досмотр по неделям'!$C$73:$C$98,Служебный!$K$2-0)),"00")) -> Неделя 8: 24.08 - 30.08 | F2: Изменение | J2: ПРИМЕР, не фактические данные. Недельные числа получены из месячных итогов июля и августа: итог месяца разделён поровну на его дни, дни сложены в недели. Для реальной работы используй пустой шаблон.
B3: Кол-во | C3: Конверсия | D3: Кол-во | E3: Конверсия | F3: Кол-во, шт | G3: Кол-во, % | H3: Конверсия, п.п.
A4: Посетители, чел. | B4: =IF(Служебный!$K$2<2,"",INDEX('Досмотр по неделям'!$D$73:$D$98,Служебный!$K$2-1)) -> 109350 | C4: — | D4: =IF(Служебный!$K$2<1,"",INDEX('Досмотр по неделям'!$D$73:$D$98,Служебный!$K$2)) -> 109350 | E4: — | F4: =IF(OR(B4="",D4=""),"-",D4-B4) -> 0 | G4: =IF(OR(B4="",D4="",B4=0),"-",D4/B4-1) -> 0 | H4: —
A5: Оружие | B5: =IF(Служебный!$K$2<2,"",INDEX('Досмотр по неделям'!$E$73:$E$98,Служебный!$K$2-1)) -> 7 | C5: =IF(OR(B5="",$B$4="",$B$4=0),"-",B5/$B$4) -> 6.4014632e-05 | D5: =IF(Служебный!$K$2<1,"",INDEX('Досмотр по неделям'!$E$73:$E$98,Служебный!$K$2)) -> 7 | E5: =IF(OR(D5="",$D$4="",$D$4=0),"-",D5/$D$4) -> 6.4014632e-05 | F5: =IF(OR(B5="",D5=""),"-",D5-B5) -> 0 | G5: =IF(OR(B5="",D5="",B5=0),"-",D5/B5-1) -> 0 | H5: =IF(OR(C5="-",E5="-"),"-",(E5-C5)*100) -> 0
A6: Колющее | B6: =IF(Служебный!$K$2<2,"",INDEX('Досмотр по неделям'!$F$73:$F$98,Служебный!$K$2-1)) -> 383 | C6: =IF(OR(B6="",$B$4="",$B$4=0),"-",B6/$B$4) -> 0.0035025149 | D6: =IF(Служебный!$K$2<1,"",INDEX('Досмотр по неделям'!$F$73:$F$98,Служебный!$K$2)) -> 383 | E6: =IF(OR(D6="",$D$4="",$D$4=0),"-",D6/$D$4) -> 0.0035025149 | F6: =IF(OR(B6="",D6=""),"-",D6-B6) -> 0 | G6: =IF(OR(B6="",D6="",B6=0),"-",D6/B6-1) -> 0 | H6: =IF(OR(C6="-",E6="-"),"-",(E6-C6)*100) -> 0
A7: Аэрозоль | B7: =IF(Служебный!$K$2<2,"",INDEX('Досмотр по неделям'!$G$73:$G$98,Служебный!$K$2-1)) -> 149 | C7: =IF(OR(B7="",$B$4="",$B$4=0),"-",B7/$B$4) -> 0.0013625972 | D7: =IF(Служебный!$K$2<1,"",INDEX('Досмотр по неделям'!$G$73:$G$98,Служебный!$K$2)) -> 149 | E7: =IF(OR(D7="",$D$4="",$D$4=0),"-",D7/$D$4) -> 0.0013625972 | F7: =IF(OR(B7="",D7=""),"-",D7-B7) -> 0 | G7: =IF(OR(B7="",D7="",B7=0),"-",D7/B7-1) -> 0 | H7: =IF(OR(C7="-",E7="-"),"-",(E7-C7)*100) -> 0
A8: Спирт | B8: =IF(Служебный!$K$2<2,"",INDEX('Досмотр по неделям'!$H$73:$H$98,Служебный!$K$2-1)) -> 131 | C8: =IF(OR(B8="",$B$4="",$B$4=0),"-",B8/$B$4) -> 0.0011979881 | D8: =IF(Служебный!$K$2<1,"",INDEX('Досмотр по неделям'!$H$73:$H$98,Служебный!$K$2)) -> 131 | E8: =IF(OR(D8="",$D$4="",$D$4=0),"-",D8/$D$4) -> 0.0011979881 | F8: =IF(OR(B8="",D8=""),"-",D8-B8) -> 0 | G8: =IF(OR(B8="",D8="",B8=0),"-",D8/B8-1) -> 0 | H8: =IF(OR(C8="-",E8="-"),"-",(E8-C8)*100) -> 0
A9: Пиротехника | B9: =IF(Служебный!$K$2<2,"",INDEX('Досмотр по неделям'!$I$73:$I$98,Служебный!$K$2-1)) -> 2 | C9: =IF(OR(B9="",$B$4="",$B$4=0),"-",B9/$B$4) -> 1.8289895e-05 | D9: =IF(Служебный!$K$2<1,"",INDEX('Досмотр по неделям'!$I$73:$I$98,Служебный!$K$2)) -> 2 | E9: =IF(OR(D9="",$D$4="",$D$4=0),"-",D9/$D$4) -> 1.8289895e-05 | F9: =IF(OR(B9="",D9=""),"-",D9-B9) -> 0 | G9: =IF(OR(B9="",D9="",B9=0),"-",D9/B9-1) -> 0 | H9: =IF(OR(C9="-",E9="-"),"-",(E9-C9)*100) -> 0
A10: Всего попыток проноса | B10: =IF(Служебный!$K$2<2,"",INDEX('Досмотр по неделям'!$J$73:$J$98,Служебный!$K$2-1)) -> 672 | C10: =IF(OR(B10="",$B$4="",$B$4=0),"-",B10/$B$4) -> 0.0061454047 | D10: =IF(Служебный!$K$2<1,"",INDEX('Досмотр по неделям'!$J$73:$J$98,Служебный!$K$2)) -> 672 | E10: =IF(OR(D10="",$D$4="",$D$4=0),"-",D10/$D$4) -> 0.0061454047 | F10: =IF(OR(B10="",D10=""),"-",D10-B10) -> 0 | G10: =IF(OR(B10="",D10="",B10=0),"-",D10/B10-1) -> 0 | H10: =IF(OR(C10="-",E10="-"),"-",(E10-C10)*100) -> 0
A12: =IF(Служебный!$K$3="","Недели текущего месяца","Недели текущего месяца: "&CHOOSE(MONTH(Служебный!$K$3),"Январь","Февраль","Март","Апрель","Май","Июнь","Июль","Август","Сентябрь","Октябрь","Ноябрь","Декабрь")&" "&YEAR(Служебный!$K$3)) -> Недели текущего месяца: Август 2026
A13: Показатель | B13: =IF(Служебный!$K$7="","Неделя 1","Неделя 1: "&TEXT(DAY(INDEX('Досмотр по неделям'!$B$73:$B$98,Служебный!$K$7)),"00")&"."&TEXT(MONTH(INDEX('Досмотр по неделям'!$B$73:$B$98,Служебный!$K$7)),"00")&" - "&TEXT(DAY(INDEX('Досмотр по неделям'!$C$73:$C$98,Служебный!$K$7)),"00")&"."&TEXT(MONTH(INDEX('Досмотр по неделям'!$C$73:$C$98,Служебный!$K$7)),"00")) -> Неделя 1: 03.08 - 09.08 | D13: =IF(Служебный!$K$8="","Неделя 2","Неделя 2: "&TEXT(DAY(INDEX('Досмотр по неделям'!$B$73:$B$98,Служебный!$K$8)),"00")&"."&TEXT(MONTH(INDEX('Досмотр по неделям'!$B$73:$B$98,Служебный!$K$8)),"00")&" - "&TEXT(DAY(INDEX('Досмотр по неделям'!$C$73:$C$98,Служебный!$K$8)),"00")&"."&TEXT(MONTH(INDEX('Досмотр по неделям'!$C$73:$C$98,Служебный!$K$8)),"00")) -> Неделя 2: 10.08 - 16.08 | F13: =IF(Служебный!$K$9="","Неделя 3","Неделя 3: "&TEXT(DAY(INDEX('Досмотр по неделям'!$B$73:$B$98,Служебный!$K$9)),"00")&"."&TEXT(MONTH(INDEX('Досмотр по неделям'!$B$73:$B$98,Служебный!$K$9)),"00")&" - "&TEXT(DAY(INDEX('Досмотр по неделям'!$C$73:$C$98,Служебный!$K$9)),"00")&"."&TEXT(MONTH(INDEX('Досмотр по неделям'!$C$73:$C$98,Служебный!$K$9)),"00")) -> Неделя 3: 17.08 - 23.08 | H13: =IF(Служебный!$K$10="","Неделя 4","Неделя 4: "&TEXT(DAY(INDEX('Досмотр по неделям'!$B$73:$B$98,Служебный!$K$10)),"00")&"."&TEXT(MONTH(INDEX('Досмотр по неделям'!$B$73:$B$98,Служебный!$K$10)),"00")&" - "&TEXT(DAY(INDEX('Досмотр по неделям'!$C$73:$C$98,Служебный!$K$10)),"00")&"."&TEXT(MONTH(INDEX('Досмотр по неделям'!$C$73:$C$98,Служебный!$K$10)),"00")) -> Неделя 4: 24.08 - 30.08 | J13: =IF(Служебный!$K$11="","Неделя 5","Неделя 5: "&TEXT(DAY(INDEX('Досмотр по неделям'!$B$73:$B$98,Служебный!$K$11)),"00")&"."&TEXT(MONTH(INDEX('Досмотр по неделям'!$B$73:$B$98,Служебный!$K$11)),"00")&" - "&TEXT(DAY(INDEX('Досмотр по неделям'!$C$73:$C$98,Служебный!$K$11)),"00")&"."&TEXT(MONTH(INDEX('Досмотр по неделям'!$C$73:$C$98,Служебный!$K$11)),"00")) -> Неделя 5: 31.08 - 06.09
B14: Кол-во | C14: Конверсия | D14: Кол-во | E14: Конверсия | F14: Кол-во | G14: Конверсия | H14: Кол-во | I14: Конверсия | J14: Кол-во | K14: Конверсия
A15: Посетители, чел. | B15: =IF(Служебный!$K$7="","",IF(INDEX('Досмотр по неделям'!$D$73:$D$98,Служебный!$K$7)="","",INDEX('Досмотр по неделям'!$D$73:$D$98,Служебный!$K$7))) -> 109350 | C15: — | D15: =IF(Служебный!$K$8="","",IF(INDEX('Досмотр по неделям'!$D$73:$D$98,Служебный!$K$8)="","",INDEX('Досмотр по неделям'!$D$73:$D$98,Служебный!$K$8))) -> 109350 | E15: — | F15: =IF(Служебный!$K$9="","",IF(INDEX('Досмотр по неделям'!$D$73:$D$98,Служебный!$K$9)="","",INDEX('Досмотр по неделям'!$D$73:$D$98,Служебный!$K$9))) -> 109350 | G15: — | H15: =IF(Служебный!$K$10="","",IF(INDEX('Досмотр по неделям'!$D$73:$D$98,Служебный!$K$10)="","",INDEX('Досмотр по неделям'!$D$73:$D$98,Служебный!$K$10))) -> 109350 | I15: — | J15: =IF(Служебный!$K$11="","",IF(INDEX('Досмотр по неделям'!$D$73:$D$98,Служебный!$K$11)="","",INDEX('Досмотр по неделям'!$D$73:$D$98,Служебный!$K$11))) | K15: —
A16: Оружие | B16: =IF(Служебный!$K$7="","",IF(INDEX('Досмотр по неделям'!$D$73:$D$98,Служебный!$K$7)="","",INDEX('Досмотр по неделям'!$E$73:$E$98,Служебный!$K$7))) -> 7 | C16: =IF(OR(B16="",B$15="",B$15=0),"",B16/B$15) -> 6.4014632e-05 | D16: =IF(Служебный!$K$8="","",IF(INDEX('Досмотр по неделям'!$D$73:$D$98,Служебный!$K$8)="","",INDEX('Досмотр по неделям'!$E$73:$E$98,Служебный!$K$8))) -> 7 | E16: =IF(OR(D16="",D$15="",D$15=0),"",D16/D$15) -> 6.4014632e-05 | F16: =IF(Служебный!$K$9="","",IF(INDEX('Досмотр по неделям'!$D$73:$D$98,Служебный!$K$9)="","",INDEX('Досмотр по неделям'!$E$73:$E$98,Служебный!$K$9))) -> 7 | G16: =IF(OR(F16="",F$15="",F$15=0),"",F16/F$15) -> 6.4014632e-05 | H16: =IF(Служебный!$K$10="","",IF(INDEX('Досмотр по неделям'!$D$73:$D$98,Служебный!$K$10)="","",INDEX('Досмотр по неделям'!$E$73:$E$98,Служебный!$K$10))) -> 7 | I16: =IF(OR(H16="",H$15="",H$15=0),"",H16/H$15) -> 6.4014632e-05 | J16: =IF(Служебный!$K$11="","",IF(INDEX('Досмотр по неделям'!$D$73:$D$98,Служебный!$K$11)="","",INDEX('Досмотр по неделям'!$E$73:$E$98,Служебный!$K$11))) | K16: =IF(OR(J16="",J$15="",J$15=0),"",J16/J$15)
A17: Колющее | B17: =IF(Служебный!$K$7="","",IF(INDEX('Досмотр по неделям'!$D$73:$D$98,Служебный!$K$7)="","",INDEX('Досмотр по неделям'!$F$73:$F$98,Служебный!$K$7))) -> 383 | C17: =IF(OR(B17="",B$15="",B$15=0),"",B17/B$15) -> 0.0035025149 | D17: =IF(Служебный!$K$8="","",IF(INDEX('Досмотр по неделям'!$D$73:$D$98,Служебный!$K$8)="","",INDEX('Досмотр по неделям'!$F$73:$F$98,Служебный!$K$8))) -> 383 | E17: =IF(OR(D17="",D$15="",D$15=0),"",D17/D$15) -> 0.0035025149 | F17: =IF(Служебный!$K$9="","",IF(INDEX('Досмотр по неделям'!$D$73:$D$98,Служебный!$K$9)="","",INDEX('Досмотр по неделям'!$F$73:$F$98,Служебный!$K$9))) -> 383 | G17: =IF(OR(F17="",F$15="",F$15=0),"",F17/F$15) -> 0.0035025149 | H17: =IF(Служебный!$K$10="","",IF(INDEX('Досмотр по неделям'!$D$73:$D$98,Служебный!$K$10)="","",INDEX('Досмотр по неделям'!$F$73:$F$98,Служебный!$K$10))) -> 383 | I17: =IF(OR(H17="",H$15="",H$15=0),"",H17/H$15) -> 0.0035025149 | J17: =IF(Служебный!$K$11="","",IF(INDEX('Досмотр по неделям'!$D$73:$D$98,Служебный!$K$11)="","",INDEX('Досмотр по неделям'!$F$73:$F$98,Служебный!$K$11))) | K17: =IF(OR(J17="",J$15="",J$15=0),"",J17/J$15)
A18: Аэрозоль | B18: =IF(Служебный!$K$7="","",IF(INDEX('Досмотр по неделям'!$D$73:$D$98,Служебный!$K$7)="","",INDEX('Досмотр по неделям'!$G$73:$G$98,Служебный!$K$7))) -> 149 | C18: =IF(OR(B18="",B$15="",B$15=0),"",B18/B$15) -> 0.0013625972 | D18: =IF(Служебный!$K$8="","",IF(INDEX('Досмотр по неделям'!$D$73:$D$98,Служебный!$K$8)="","",INDEX('Досмотр по неделям'!$G$73:$G$98,Служебный!$K$8))) -> 149 | E18: =IF(OR(D18="",D$15="",D$15=0),"",D18/D$15) -> 0.0013625972 | F18: =IF(Служебный!$K$9="","",IF(INDEX('Досмотр по неделям'!$D$73:$D$98,Служебный!$K$9)="","",INDEX('Досмотр по неделям'!$G$73:$G$98,Служебный!$K$9))) -> 149 | G18: =IF(OR(F18="",F$15="",F$15=0),"",F18/F$15) -> 0.0013625972 | H18: =IF(Служебный!$K$10="","",IF(INDEX('Досмотр по неделям'!$D$73:$D$98,Служебный!$K$10)="","",INDEX('Досмотр по неделям'!$G$73:$G$98,Служебный!$K$10))) -> 149 | I18: =IF(OR(H18="",H$15="",H$15=0),"",H18/H$15) -> 0.0013625972 | J18: =IF(Служебный!$K$11="","",IF(INDEX('Досмотр по неделям'!$D$73:$D$98,Служебный!$K$11)="","",INDEX('Досмотр по неделям'!$G$73:$G$98,Служебный!$K$11))) | K18: =IF(OR(J18="",J$15="",J$15=0),"",J18/J$15)
A19: Спирт | B19: =IF(Служебный!$K$7="","",IF(INDEX('Досмотр по неделям'!$D$73:$D$98,Служебный!$K$7)="","",INDEX('Досмотр по неделям'!$H$73:$H$98,Служебный!$K$7))) -> 131 | C19: =IF(OR(B19="",B$15="",B$15=0),"",B19/B$15) -> 0.0011979881 | D19: =IF(Служебный!$K$8="","",IF(INDEX('Досмотр по неделям'!$D$73:$D$98,Служебный!$K$8)="","",INDEX('Досмотр по неделям'!$H$73:$H$98,Служебный!$K$8))) -> 131 | E19: =IF(OR(D19="",D$15="",D$15=0),"",D19/D$15) -> 0.0011979881 | F19: =IF(Служебный!$K$9="","",IF(INDEX('Досмотр по неделям'!$D$73:$D$98,Служебный!$K$9)="","",INDEX('Досмотр по неделям'!$H$73:$H$98,Служебный!$K$9))) -> 131 | G19: =IF(OR(F19="",F$15="",F$15=0),"",F19/F$15) -> 0.0011979881 | H19: =IF(Служебный!$K$10="","",IF(INDEX('Досмотр по неделям'!$D$73:$D$98,Служебный!$K$10)="","",INDEX('Досмотр по неделям'!$H$73:$H$98,Служебный!$K$10))) -> 131 | I19: =IF(OR(H19="",H$15="",H$15=0),"",H19/H$15) -> 0.0011979881 | J19: =IF(Служебный!$K$11="","",IF(INDEX('Досмотр по неделям'!$D$73:$D$98,Служебный!$K$11)="","",INDEX('Досмотр по неделям'!$H$73:$H$98,Служебный!$K$11))) | K19: =IF(OR(J19="",J$15="",J$15=0),"",J19/J$15)
A20: Пиротехника | B20: =IF(Служебный!$K$7="","",IF(INDEX('Досмотр по неделям'!$D$73:$D$98,Служебный!$K$7)="","",INDEX('Досмотр по неделям'!$I$73:$I$98,Служебный!$K$7))) -> 2 | C20: =IF(OR(B20="",B$15="",B$15=0),"",B20/B$15) -> 1.8289895e-05 | D20: =IF(Служебный!$K$8="","",IF(INDEX('Досмотр по неделям'!$D$73:$D$98,Служебный!$K$8)="","",INDEX('Досмотр по неделям'!$I$73:$I$98,Служебный!$K$8))) -> 2 | E20: =IF(OR(D20="",D$15="",D$15=0),"",D20/D$15) -> 1.8289895e-05 | F20: =IF(Служебный!$K$9="","",IF(INDEX('Досмотр по неделям'!$D$73:$D$98,Служебный!$K$9)="","",INDEX('Досмотр по неделям'!$I$73:$I$98,Служебный!$K$9))) -> 2 | G20: =IF(OR(F20="",F$15="",F$15=0),"",F20/F$15) -> 1.8289895e-05 | H20: =IF(Служебный!$K$10="","",IF(INDEX('Досмотр по неделям'!$D$73:$D$98,Служебный!$K$10)="","",INDEX('Досмотр по неделям'!$I$73:$I$98,Служебный!$K$10))) -> 2 | I20: =IF(OR(H20="",H$15="",H$15=0),"",H20/H$15) -> 1.8289895e-05 | J20: =IF(Служебный!$K$11="","",IF(INDEX('Досмотр по неделям'!$D$73:$D$98,Служебный!$K$11)="","",INDEX('Досмотр по неделям'!$I$73:$I$98,Служебный!$K$11))) | K20: =IF(OR(J20="",J$15="",J$15=0),"",J20/J$15)
A21: Всего попыток проноса | B21: =IF(Служебный!$K$7="","",IF(INDEX('Досмотр по неделям'!$D$73:$D$98,Служебный!$K$7)="","",INDEX('Досмотр по неделям'!$J$73:$J$98,Служебный!$K$7))) -> 672 | C21: =IF(OR(B21="",B$15="",B$15=0),"",B21/B$15) -> 0.0061454047 | D21: =IF(Служебный!$K$8="","",IF(INDEX('Досмотр по неделям'!$D$73:$D$98,Служебный!$K$8)="","",INDEX('Досмотр по неделям'!$J$73:$J$98,Служебный!$K$8))) -> 672 | E21: =IF(OR(D21="",D$15="",D$15=0),"",D21/D$15) -> 0.0061454047 | F21: =IF(Служебный!$K$9="","",IF(INDEX('Досмотр по неделям'!$D$73:$D$98,Служебный!$K$9)="","",INDEX('Досмотр по неделям'!$J$73:$J$98,Служебный!$K$9))) -> 672 | G21: =IF(OR(F21="",F$15="",F$15=0),"",F21/F$15) -> 0.0061454047 | H21: =IF(Служебный!$K$10="","",IF(INDEX('Досмотр по неделям'!$D$73:$D$98,Служебный!$K$10)="","",INDEX('Досмотр по неделям'!$J$73:$J$98,Служебный!$K$10))) -> 672 | I21: =IF(OR(H21="",H$15="",H$15=0),"",H21/H$15) -> 0.0061454047 | J21: =IF(Служебный!$K$11="","",IF(INDEX('Досмотр по неделям'!$D$73:$D$98,Служебный!$K$11)="","",INDEX('Досмотр по неделям'!$J$73:$J$98,Служебный!$K$11))) | K21: =IF(OR(J21="",J$15="",J$15=0),"",J21/J$15)
A22: Цвет конверсии по строке: зелёная неделя с наименьшей долей изъятий, красная с наибольшей.
A24: Месяц к месяцу: текущий против прошлого
A25: Показатель | B25: =IF(Служебный!$K$4="","-",CHOOSE(MONTH(Служебный!$K$4),"Январь","Февраль","Март","Апрель","Май","Июнь","Июль","Август","Сентябрь","Октябрь","Ноябрь","Декабрь")&" "&YEAR(Служебный!$K$4)&" (недель: "&COUNTIFS('Досмотр по неделям'!$B$73:$B$98,">="&Служебный!$K$4,'Досмотр по неделям'!$B$73:$B$98,"<"&Служебный!$K$3,'Досмотр по неделям'!$D$73:$D$98,"<>")&")") -> Июль 2026 (недель: 4) | D25: =IF(Служебный!$K$3="","-",CHOOSE(MONTH(Служебный!$K$3),"Январь","Февраль","Март","Апрель","Май","Июнь","Июль","Август","Сентябрь","Октябрь","Ноябрь","Декабрь")&" "&YEAR(Служебный!$K$3)&" (недель: "&COUNTIFS('Досмотр по неделям'!$B$73:$B$98,">="&Служебный!$K$3,'Досмотр по неделям'!$B$73:$B$98,"<"&Служебный!$K$5,'Досмотр по неделям'!$D$73:$D$98,"<>")&")") -> Август 2026 (недель: 4) | F25: Изменение
B26: Кол-во | C26: Конверсия | D26: Кол-во | E26: Конверсия | F26: Кол-во, шт | G26: Кол-во, % | H26: Конверсия, п.п.
A27: Посетители, чел. | B27: =IF(Служебный!$K$4="","",IF(COUNTIFS('Досмотр по неделям'!$B$73:$B$98,">="&Служебный!$K$4,'Досмотр по неделям'!$B$73:$B$98,"<"&Служебный!$K$3,'Досмотр по неделям'!$D$73:$D$98,"<>")=0,"",SUMIFS('Досмотр по неделям'!$D$73:$D$98,'Досмотр по неделям'!$B$73:$B$98,">="&Служебный!$K$4,'Досмотр по неделям'!$B$73:$B$98,"<"&Служебный!$K$3))) -> 397460 | C27: — | D27: =IF(Служебный!$K$3="","",IF(COUNTIFS('Досмотр по неделям'!$B$73:$B$98,">="&Служебный!$K$3,'Досмотр по неделям'!$B$73:$B$98,"<"&Служебный!$K$5,'Досмотр по неделям'!$D$73:$D$98,"<>")=0,"",SUMIFS('Досмотр по неделям'!$D$73:$D$98,'Досмотр по неделям'!$B$73:$B$98,">="&Служебный!$K$3,'Досмотр по неделям'!$B$73:$B$98,"<"&Служебный!$K$5))) -> 437400 | E27: — | F27: =IF(OR(B27="",D27=""),"-",D27-B27) -> 39940 | G27: =IF(OR(B27="",D27="",B27=0),"-",D27/B27-1) -> 0.1004881 | H27: —
A28: Оружие | B28: =IF(Служебный!$K$4="","",IF(COUNTIFS('Досмотр по неделям'!$B$73:$B$98,">="&Служебный!$K$4,'Досмотр по неделям'!$B$73:$B$98,"<"&Служебный!$K$3,'Досмотр по неделям'!$D$73:$D$98,"<>")=0,"",SUMIFS('Досмотр по неделям'!$E$73:$E$98,'Досмотр по неделям'!$B$73:$B$98,">="&Служебный!$K$4,'Досмотр по неделям'!$B$73:$B$98,"<"&Служебный!$K$3))) -> 21 | C28: =IF(OR(B28="",$B$27="",$B$27=0),"-",B28/$B$27) -> 5.2835505e-05 | D28: =IF(Служебный!$K$3="","",IF(COUNTIFS('Досмотр по неделям'!$B$73:$B$98,">="&Служебный!$K$3,'Досмотр по неделям'!$B$73:$B$98,"<"&Служебный!$K$5,'Досмотр по неделям'!$D$73:$D$98,"<>")=0,"",SUMIFS('Досмотр по неделям'!$E$73:$E$98,'Досмотр по неделям'!$B$73:$B$98,">="&Служебный!$K$3,'Досмотр по неделям'!$B$73:$B$98,"<"&Служебный!$K$5))) -> 28 | E28: =IF(OR(D28="",$D$27="",$D$27=0),"-",D28/$D$27) -> 6.4014632e-05 | F28: =IF(OR(B28="",D28=""),"-",D28-B28) -> 7 | G28: =IF(OR(B28="",D28="",B28=0),"-",D28/B28-1) -> 0.33333333 | H28: =IF(OR(C28="-",E28="-"),"-",(E28-C28)*100) -> 0.0011179126
A29: Колющее | B29: =IF(Служебный!$K$4="","",IF(COUNTIFS('Досмотр по неделям'!$B$73:$B$98,">="&Служебный!$K$4,'Досмотр по неделям'!$B$73:$B$98,"<"&Служебный!$K$3,'Досмотр по неделям'!$D$73:$D$98,"<>")=0,"",SUMIFS('Досмотр по неделям'!$F$73:$F$98,'Досмотр по неделям'!$B$73:$B$98,">="&Служебный!$K$4,'Досмотр по неделям'!$B$73:$B$98,"<"&Служебный!$K$3))) -> 1547 | C29: =IF(OR(B29="",$B$27="",$B$27=0),"-",B29/$B$27) -> 0.0038922156 | D29: =IF(Служебный!$K$3="","",IF(COUNTIFS('Досмотр по неделям'!$B$73:$B$98,">="&Служебный!$K$3,'Досмотр по неделям'!$B$73:$B$98,"<"&Служебный!$K$5,'Досмотр по неделям'!$D$73:$D$98,"<>")=0,"",SUMIFS('Досмотр по неделям'!$F$73:$F$98,'Досмотр по неделям'!$B$73:$B$98,">="&Служебный!$K$3,'Досмотр по неделям'!$B$73:$B$98,"<"&Служебный!$K$5))) -> 1532 | E29: =IF(OR(D29="",$D$27="",$D$27=0),"-",D29/$D$27) -> 0.0035025149 | F29: =IF(OR(B29="",D29=""),"-",D29-B29) -> -15 | G29: =IF(OR(B29="",D29="",B29=0),"-",D29/B29-1) -> -0.0096961862 | H29: =IF(OR(C29="-",E29="-"),"-",(E29-C29)*100) -> -0.038970071
A30: Аэрозоль | B30: =IF(Служебный!$K$4="","",IF(COUNTIFS('Досмотр по неделям'!$B$73:$B$98,">="&Служебный!$K$4,'Досмотр по неделям'!$B$73:$B$98,"<"&Служебный!$K$3,'Досмотр по неделям'!$D$73:$D$98,"<>")=0,"",SUMIFS('Досмотр по неделям'!$G$73:$G$98,'Досмотр по неделям'!$B$73:$B$98,">="&Служебный!$K$4,'Досмотр по неделям'!$B$73:$B$98,"<"&Служебный!$K$3))) -> 774 | C30: =IF(OR(B30="",$B$27="",$B$27=0),"-",B30/$B$27) -> 0.0019473658 | D30: =IF(Служебный!$K$3="","",IF(COUNTIFS('Досмотр по неделям'!$B$73:$B$98,">="&Служебный!$K$3,'Досмотр по неделям'!$B$73:$B$98,"<"&Служебный!$K$5,'Досмотр по неделям'!$D$73:$D$98,"<>")=0,"",SUMIFS('Досмотр по неделям'!$G$73:$G$98,'Досмотр по неделям'!$B$73:$B$98,">="&Служебный!$K$3,'Досмотр по неделям'!$B$73:$B$98,"<"&Служебный!$K$5))) -> 596 | E30: =IF(OR(D30="",$D$27="",$D$27=0),"-",D30/$D$27) -> 0.0013625972 | F30: =IF(OR(B30="",D30=""),"-",D30-B30) -> -178 | G30: =IF(OR(B30="",D30="",B30=0),"-",D30/B30-1) -> -0.22997416 | H30: =IF(OR(C30="-",E30="-"),"-",(E30-C30)*100) -> -0.058476861
A31: Спирт | B31: =IF(Служебный!$K$4="","",IF(COUNTIFS('Досмотр по неделям'!$B$73:$B$98,">="&Служебный!$K$4,'Досмотр по неделям'!$B$73:$B$98,"<"&Служебный!$K$3,'Досмотр по неделям'!$D$73:$D$98,"<>")=0,"",SUMIFS('Досмотр по неделям'!$H$73:$H$98,'Досмотр по неделям'!$B$73:$B$98,">="&Служебный!$K$4,'Досмотр по неделям'!$B$73:$B$98,"<"&Служебный!$K$3))) -> 513 | C31: =IF(OR(B31="",$B$27="",$B$27=0),"-",B31/$B$27) -> 0.0012906959 | D31: =IF(Служебный!$K$3="","",IF(COUNTIFS('Досмотр по неделям'!$B$73:$B$98,">="&Служебный!$K$3,'Досмотр по неделям'!$B$73:$B$98,"<"&Служебный!$K$5,'Досмотр по неделям'!$D$73:$D$98,"<>")=0,"",SUMIFS('Досмотр по неделям'!$H$73:$H$98,'Досмотр по неделям'!$B$73:$B$98,">="&Служебный!$K$3,'Досмотр по неделям'!$B$73:$B$98,"<"&Служебный!$K$5))) -> 524 | E31: =IF(OR(D31="",$D$27="",$D$27=0),"-",D31/$D$27) -> 0.0011979881 | F31: =IF(OR(B31="",D31=""),"-",D31-B31) -> 11 | G31: =IF(OR(B31="",D31="",B31=0),"-",D31/B31-1) -> 0.021442495 | H31: =IF(OR(C31="-",E31="-"),"-",(E31-C31)*100) -> -0.0092707808
A32: Пиротехника | B32: =IF(Служебный!$K$4="","",IF(COUNTIFS('Досмотр по неделям'!$B$73:$B$98,">="&Служебный!$K$4,'Досмотр по неделям'!$B$73:$B$98,"<"&Служебный!$K$3,'Досмотр по неделям'!$D$73:$D$98,"<>")=0,"",SUMIFS('Досмотр по неделям'!$I$73:$I$98,'Досмотр по неделям'!$B$73:$B$98,">="&Служебный!$K$4,'Досмотр по неделям'!$B$73:$B$98,"<"&Служебный!$K$3))) -> 4 | C32: =IF(OR(B32="",$B$27="",$B$27=0),"-",B32/$B$27) -> 1.0063906e-05 | D32: =IF(Служебный!$K$3="","",IF(COUNTIFS('Досмотр по неделям'!$B$73:$B$98,">="&Служебный!$K$3,'Досмотр по неделям'!$B$73:$B$98,"<"&Служебный!$K$5,'Досмотр по неделям'!$D$73:$D$98,"<>")=0,"",SUMIFS('Досмотр по неделям'!$I$73:$I$98,'Досмотр по неделям'!$B$73:$B$98,">="&Служебный!$K$3,'Досмотр по неделям'!$B$73:$B$98,"<"&Служебный!$K$5))) -> 8 | E32: =IF(OR(D32="",$D$27="",$D$27=0),"-",D32/$D$27) -> 1.8289895e-05 | F32: =IF(OR(B32="",D32=""),"-",D32-B32) -> 4 | G32: =IF(OR(B32="",D32="",B32=0),"-",D32/B32-1) -> 1 | H32: =IF(OR(C32="-",E32="-"),"-",(E32-C32)*100) -> 0.0008225989
A33: Всего попыток проноса | B33: =IF(Служебный!$K$4="","",IF(COUNTIFS('Досмотр по неделям'!$B$73:$B$98,">="&Служебный!$K$4,'Досмотр по неделям'!$B$73:$B$98,"<"&Служебный!$K$3,'Досмотр по неделям'!$D$73:$D$98,"<>")=0,"",SUMIFS('Досмотр по неделям'!$J$73:$J$98,'Досмотр по неделям'!$B$73:$B$98,">="&Служебный!$K$4,'Досмотр по неделям'!$B$73:$B$98,"<"&Служебный!$K$3))) -> 2859 | C33: =IF(OR(B33="",$B$27="",$B$27=0),"-",B33/$B$27) -> 0.0071931767 | D33: =IF(Служебный!$K$3="","",IF(COUNTIFS('Досмотр по неделям'!$B$73:$B$98,">="&Служебный!$K$3,'Досмотр по неделям'!$B$73:$B$98,"<"&Служебный!$K$5,'Досмотр по неделям'!$D$73:$D$98,"<>")=0,"",SUMIFS('Досмотр по неделям'!$J$73:$J$98,'Досмотр по неделям'!$B$73:$B$98,">="&Служебный!$K$3,'Досмотр по неделям'!$B$73:$B$98,"<"&Служебный!$K$5))) -> 2688 | E33: =IF(OR(D33="",$D$27="",$D$27=0),"-",D33/$D$27) -> 0.0061454047 | F33: =IF(OR(B33="",D33=""),"-",D33-B33) -> -171 | G33: =IF(OR(B33="",D33="",B33=0),"-",D33/B33-1) -> -0.059811123 | H33: =IF(OR(C33="-",E33="-"),"-",(E33-C33)*100) -> -0.1047772
A34: Текущий месяц может быть неполным: сравнивай с учётом числа недель в заголовке.
A71: Журнал по неделям
A72: № | B72: С | C72: По | D72: Посетители | E72: Оружие | F72: Колющее | G72: Аэрозоль | H72: Спирт | I72: Пиротехника | J72: Всего попыток проноса | K72: Конв. оружие | L72: Конв. колющее | M72: Конв. аэрозоль | N72: Конв. спирт | O72: Конв. пиротехника | P72: Конв. всего
A73: 1 | B73: 46209 | C73: =B73+6 -> 46215 | D73: 98597 | E73: 5 | F73: 387 | G73: 197 | H73: 128 | I73: 1 | J73: =IF(COUNT(E73:I73)=0,"",SUM(E73:I73)) -> 718 | K73: =IF(OR(D73="",E73="",D73=0),"",E73/D73) -> 5.0711482e-05 | L73: =IF(OR(D73="",F73="",D73=0),"",F73/D73) -> 0.0039250687 | M73: =IF(OR(D73="",G73="",D73=0),"",G73/D73) -> 0.0019980324 | N73: =IF(OR(D73="",H73="",D73=0),"",H73/D73) -> 0.0012982139 | O73: =IF(OR(D73="",I73="",D73=0),"",I73/D73) -> 1.0142296e-05 | P73: =IF(OR(D73="",J73="",D73=0),"",J73/D73) -> 0.0072821688
A74: 2 | B74: =B73+7 -> 46216 | C74: =B74+6 -> 46222 | D74: 98597 | E74: 5 | F74: 387 | G74: 197 | H74: 128 | I74: 1 | J74: =IF(COUNT(E74:I74)=0,"",SUM(E74:I74)) -> 718 | K74: =IF(OR(D74="",E74="",D74=0),"",E74/D74) -> 5.0711482e-05 | L74: =IF(OR(D74="",F74="",D74=0),"",F74/D74) -> 0.0039250687 | M74: =IF(OR(D74="",G74="",D74=0),"",G74/D74) -> 0.0019980324 | N74: =IF(OR(D74="",H74="",D74=0),"",H74/D74) -> 0.0012982139 | O74: =IF(OR(D74="",I74="",D74=0),"",I74/D74) -> 1.0142296e-05 | P74: =IF(OR(D74="",J74="",D74=0),"",J74/D74) -> 0.0072821688
A75: 3 | B75: =B74+7 -> 46223 | C75: =B75+6 -> 46229 | D75: 98597 | E75: 5 | F75: 387 | G75: 197 | H75: 128 | I75: 1 | J75: =IF(COUNT(E75:I75)=0,"",SUM(E75:I75)) -> 718 | K75: =IF(OR(D75="",E75="",D75=0),"",E75/D75) -> 5.0711482e-05 | L75: =IF(OR(D75="",F75="",D75=0),"",F75/D75) -> 0.0039250687 | M75: =IF(OR(D75="",G75="",D75=0),"",G75/D75) -> 0.0019980324 | N75: =IF(OR(D75="",H75="",D75=0),"",H75/D75) -> 0.0012982139 | O75: =IF(OR(D75="",I75="",D75=0),"",I75/D75) -> 1.0142296e-05 | P75: =IF(OR(D75="",J75="",D75=0),"",J75/D75) -> 0.0072821688
A76: 4 | B76: =B75+7 -> 46230 | C76: =B76+6 -> 46236 | D76: 101669 | E76: 6 | F76: 386 | G76: 183 | H76: 129 | I76: 1 | J76: =IF(COUNT(E76:I76)=0,"",SUM(E76:I76)) -> 705 | K76: =IF(OR(D76="",E76="",D76=0),"",E76/D76) -> 5.9015039e-05 | L76: =IF(OR(D76="",F76="",D76=0),"",F76/D76) -> 0.0037966342 | M76: =IF(OR(D76="",G76="",D76=0),"",G76/D76) -> 0.0017999587 | N76: =IF(OR(D76="",H76="",D76=0),"",H76/D76) -> 0.0012688233 | O76: =IF(OR(D76="",I76="",D76=0),"",I76/D76) -> 9.8358398e-06 | P76: =IF(OR(D76="",J76="",D76=0),"",J76/D76) -> 0.0069342671
A77: 5 | B77: =B76+7 -> 46237 | C77: =B77+6 -> 46243 | D77: 109350 | E77: 7 | F77: 383 | G77: 149 | H77: 131 | I77: 2 | J77: =IF(COUNT(E77:I77)=0,"",SUM(E77:I77)) -> 672 | K77: =IF(OR(D77="",E77="",D77=0),"",E77/D77) -> 6.4014632e-05 | L77: =IF(OR(D77="",F77="",D77=0),"",F77/D77) -> 0.0035025149 | M77: =IF(OR(D77="",G77="",D77=0),"",G77/D77) -> 0.0013625972 | N77: =IF(OR(D77="",H77="",D77=0),"",H77/D77) -> 0.0011979881 | O77: =IF(OR(D77="",I77="",D77=0),"",I77/D77) -> 1.8289895e-05 | P77: =IF(OR(D77="",J77="",D77=0),"",J77/D77) -> 0.0061454047
A78: 6 | B78: =B77+7 -> 46244 | C78: =B78+6 -> 46250 | D78: 109350 | E78: 7 | F78: 383 | G78: 149 | H78: 131 | I78: 2 | J78: =IF(COUNT(E78:I78)=0,"",SUM(E78:I78)) -> 672 | K78: =IF(OR(D78="",E78="",D78=0),"",E78/D78) -> 6.4014632e-05 | L78: =IF(OR(D78="",F78="",D78=0),"",F78/D78) -> 0.0035025149 | M78: =IF(OR(D78="",G78="",D78=0),"",G78/D78) -> 0.0013625972 | N78: =IF(OR(D78="",H78="",D78=0),"",H78/D78) -> 0.0011979881 | O78: =IF(OR(D78="",I78="",D78=0),"",I78/D78) -> 1.8289895e-05 | P78: =IF(OR(D78="",J78="",D78=0),"",J78/D78) -> 0.0061454047
...

Sheet Служебный
A1: Данные графика: ссылки на журнал. #Н/Д = неделя не заполнена или изъятий 0 (на логарифмической шкале ноль не рисуется). | J1: Опорные значения для таблиц
A2: Неделя | B2: Посетители | C2: Оружие | D2: Колющее | E2: Аэрозоль | F2: Спирт | G2: Пиротехника | H2: Всего попыток проноса | J2: Последняя заполненная неделя (№) | K2: =COUNT('Досмотр по неделям'!$D$73:$D$98) -> 8
A3: =TEXT(DAY('Досмотр по неделям'!B73),"00")&"."&TEXT(MONTH('Досмотр по неделям'!B73),"00") -> 06.07 | B3: =IF('Досмотр по неделям'!D73="",NA(),'Досмотр по неделям'!D73) -> 98597 | C3: =IF(OR('Досмотр по неделям'!K73="",'Досмотр по неделям'!K73=0),NA(),'Досмотр по неделям'!K73) -> 5.0711482e-05 | D3: =IF(OR('Досмотр по неделям'!L73="",'Досмотр по неделям'!L73=0),NA(),'Досмотр по неделям'!L73) -> 0.0039250687 | E3: =IF(OR('Досмотр по неделям'!M73="",'Досмотр по неделям'!M73=0),NA(),'Досмотр по неделям'!M73) -> 0.0019980324 | F3: =IF(OR('Досмотр по неделям'!N73="",'Досмотр по неделям'!N73=0),NA(),'Досмотр по неделям'!N73) -> 0.0012982139 | G3: =IF(OR('Досмотр по неделям'!O73="",'Досмотр по неделям'!O73=0),NA(),'Досмотр по неделям'!O73) -> 1.0142296e-05 | H3: =IF(OR('Досмотр по неделям'!P73="",'Досмотр по неделям'!P73=0),NA(),'Досмотр по неделям'!P73) -> 0.0072821688 | J3: Начало текущего месяца | K3: =IF(K2=0,"",DATE(YEAR(INDEX('Досмотр по неделям'!$B$73:$B$98,K2)),MONTH(INDEX('Досмотр по неделям'!$B$73:$B$98,K2)),1)) -> 46235
A4: =TEXT(DAY('Досмотр по неделям'!B74),"00")&"."&TEXT(MONTH('Досмотр по неделям'!B74),"00") -> 13.07 | B4: =IF('Досмотр по неделям'!D74="",NA(),'Досмотр по неделям'!D74) -> 98597 | C4: =IF(OR('Досмотр по неделям'!K74="",'Досмотр по неделям'!K74=0),NA(),'Досмотр по неделям'!K74) -> 5.0711482e-05 | D4: =IF(OR('Досмотр по неделям'!L74="",'Досмотр по неделям'!L74=0),NA(),'Досмотр по неделям'!L74) -> 0.0039250687 | E4: =IF(OR('Досмотр по неделям'!M74="",'Досмотр по неделям'!M74=0),NA(),'Досмотр по неделям'!M74) -> 0.0019980324 | F4: =IF(OR('Досмотр по неделям'!N74="",'Досмотр по неделям'!N74=0),NA(),'Досмотр по неделям'!N74) -> 0.0012982139 | G4: =IF(OR('Досмотр по неделям'!O74="",'Досмотр по неделям'!O74=0),NA(),'Досмотр по неделям'!O74) -> 1.0142296e-05 | H4: =IF(OR('Досмотр по неделям'!P74="",'Досмотр по неделям'!P74=0),NA(),'Досмотр по неделям'!P74) -> 0.0072821688 | J4: Начало прошлого месяца | K4: =IF(K3="","",EDATE(K3,-1)) -> 46204
A5: =TEXT(DAY('Досмотр по неделям'!B75),"00")&"."&TEXT(MONTH('Досмотр по неделям'!B75),"00") -> 20.07 | B5: =IF('Досмотр по неделям'!D75="",NA(),'Досмотр по неделям'!D75) -> 98597 | C5: =IF(OR('Досмотр по неделям'!K75="",'Досмотр по неделям'!K75=0),NA(),'Досмотр по неделям'!K75) -> 5.0711482e-05 | D5: =IF(OR('Досмотр по неделям'!L75="",'Досмотр по неделям'!L75=0),NA(),'Досмотр по неделям'!L75) -> 0.0039250687 | E5: =IF(OR('Досмотр по неделям'!M75="",'Досмотр по неделям'!M75=0),NA(),'Досмотр по неделям'!M75) -> 0.0019980324 | F5: =IF(OR('Досмотр по неделям'!N75="",'Досмотр по неделям'!N75=0),NA(),'Досмотр по неделям'!N75) -> 0.0012982139 | G5: =IF(OR('Досмотр по неделям'!O75="",'Досмотр по неделям'!O75=0),NA(),'Досмотр по неделям'!O75) -> 1.0142296e-05 | H5: =IF(OR('Досмотр по неделям'!P75="",'Досмотр по неделям'!P75=0),NA(),'Досмотр по неделям'!P75) -> 0.0072821688 | J5: Начало следующего месяца | K5: =IF(K3="","",EDATE(K3,1)) -> 46266
A6: =TEXT(DAY('Досмотр по неделям'!B76),"00")&"."&TEXT(MONTH('Досмотр по неделям'!B76),"00") -> 27.07 | B6: =IF('Досмотр по неделям'!D76="",NA(),'Досмотр по неделям'!D76) -> 101669 | C6: =IF(OR('Досмотр по неделям'!K76="",'Досмотр по неделям'!K76=0),NA(),'Досмотр по неделям'!K76) -> 5.9015039e-05 | D6: =IF(OR('Досмотр по неделям'!L76="",'Досмотр по неделям'!L76=0),NA(),'Досмотр по неделям'!L76) -> 0.0037966342 | E6: =IF(OR('Досмотр по неделям'!M76="",'Досмотр по неделям'!M76=0),NA(),'Досмотр по неделям'!M76) -> 0.0017999587 | F6: =IF(OR('Досмотр по неделям'!N76="",'Досмотр по неделям'!N76=0),NA(),'Досмотр по неделям'!N76) -> 0.0012688233 | G6: =IF(OR('Досмотр по неделям'!O76="",'Досмотр по неделям'!O76=0),NA(),'Досмотр по неделям'!O76) -> 9.8358398e-06 | H6: =IF(OR('Досмотр по неделям'!P76="",'Досмотр по неделям'!P76=0),NA(),'Досмотр по неделям'!P76) -> 0.0069342671 | J6: Первая неделя текущего месяца (№) | K6: =IF(K3="","",COUNTIF('Досмотр по неделям'!$B$73:$B$98,"<"&K3)+1) -> 5
A7: =TEXT(DAY('Досмотр по неделям'!B77),"00")&"."&TEXT(MONTH('Досмотр по неделям'!B77),"00") -> 03.08 | B7: =IF('Досмотр по неделям'!D77="",NA(),'Досмотр по неделям'!D77) -> 109350 | C7: =IF(OR('Досмотр по неделям'!K77="",'Досмотр по неделям'!K77=0),NA(),'Досмотр по неделям'!K77) -> 6.4014632e-05 | D7: =IF(OR('Досмотр по неделям'!L77="",'Досмотр по неделям'!L77=0),NA(),'Досмотр по неделям'!L77) -> 0.0035025149 | E7: =IF(OR('Досмотр по неделям'!M77="",'Досмотр по неделям'!M77=0),NA(),'Досмотр по неделям'!M77) -> 0.0013625972 | F7: =IF(OR('Досмотр по неделям'!N77="",'Досмотр по неделям'!N77=0),NA(),'Досмотр по неделям'!N77) -> 0.0011979881 | G7: =IF(OR('Досмотр по неделям'!O77="",'Досмотр по неделям'!O77=0),NA(),'Досмотр по неделям'!O77) -> 1.8289895e-05 | H7: =IF(OR('Досмотр по неделям'!P77="",'Досмотр по неделям'!P77=0),NA(),'Досмотр по неделям'!P77) -> 0.0061454047 | J7: Неделя 1 текущего месяца (№) | K7: =IF(K6="","",IF(K6+0>26,"",IF(INDEX('Досмотр по неделям'!$B$73:$B$98,K6+0)<K5,K6+0,""))) -> 5
A8: =TEXT(DAY('Досмотр по неделям'!B78),"00")&"."&TEXT(MONTH('Досмотр по неделям'!B78),"00") -> 10.08 | B8: =IF('Досмотр по неделям'!D78="",NA(),'Досмотр по неделям'!D78) -> 109350 | C8: =IF(OR('Досмотр по неделям'!K78="",'Досмотр по неделям'!K78=0),NA(),'Досмотр по неделям'!K78) -> 6.4014632e-05 | D8: =IF(OR('Досмотр по неделям'!L78="",'Досмотр по неделям'!L78=0),NA(),'Досмотр по неделям'!L78) -> 0.0035025149 | E8: =IF(OR('Досмотр по неделям'!M78="",'Досмотр по неделям'!M78=0),NA(),'Досмотр по неделям'!M78) -> 0.0013625972 | F8: =IF(OR('Досмотр по неделям'!N78="",'Досмотр по неделям'!N78=0),NA(),'Досмотр по неделям'!N78) -> 0.0011979881 | G8: =IF(OR('Досмотр по неделям'!O78="",'Досмотр по неделям'!O78=0),NA(),'Досмотр по неделям'!O78) -> 1.8289895e-05 | H8: =IF(OR('Досмотр по неделям'!P78="",'Досмотр по неделям'!P78=0),NA(),'Досмотр по неделям'!P78) -> 0.0061454047 | J8: Неделя 2 текущего месяца (№) | K8: =IF(K6="","",IF(K6+1>26,"",IF(INDEX('Досмотр по неделям'!$B$73:$B$98,K6+1)<K5,K6+1,""))) -> 6
A9: =TEXT(DAY('Досмотр по неделям'!B79),"00")&"."&TEXT(MONTH('Досмотр по неделям'!B79),"00") -> 17.08 | B9: =IF('Досмотр по неделям'!D79="",NA(),'Досмотр по неделям'!D79) -> 109350 | C9: =IF(OR('Досмотр по неделям'!K79="",'Досмотр по неделям'!K79=0),NA(),'Досмотр по неделям'!K79) -> 6.4014632e-05 | D9: =IF(OR('Досмотр по неделям'!L79="",'Досмотр по неделям'!L79=0),NA(),'Досмотр по неделям'!L79) -> 0.0035025149 | E9: =IF(OR('Досмотр по неделям'!M79="",'Досмотр по неделям'!M79=0),NA(),'Досмотр по неделям'!M79) -> 0.0013625972 | F9: =IF(OR('Досмотр по неделям'!N79="",'Досмотр по неделям'!N79=0),NA(),'Досмотр по неделям'!N79) -> 0.0011979881 | G9: =IF(OR('Досмотр по неделям'!O79="",'Досмотр по неделям'!O79=0),NA(),'Досмотр по неделям'!O79) -> 1.8289895e-05 | H9: =IF(OR('Досмотр по неделям'!P79="",'Досмотр по неделям'!P79=0),NA(),'Досмотр по неделям'!P79) -> 0.0061454047 | J9: Неделя 3 текущего месяца (№) | K9: =IF(K6="","",IF(K6+2>26,"",IF(INDEX('Досмотр по неделям'!$B$73:$B$98,K6+2)<K5,K6+2,""))) -> 7
A10: =TEXT(DAY('Досмотр по неделям'!B80),"00")&"."&TEXT(MONTH('Досмотр по неделям'!B80),"00") -> 24.08 | B10: =IF('Досмотр по неделям'!D80="",NA(),'Досмотр по неделям'!D80) -> 109350 | C10: =IF(OR('Досмотр по неделям'!K80="",'Досмотр по неделям'!K80=0),NA(),'Досмотр по неделям'!K80) -> 6.4014632e-05 | D10: =IF(OR('Досмотр по неделям'!L80="",'Досмотр по неделям'!L80=0),NA(),'Досмотр по неделям'!L80) -> 0.0035025149 | E10: =IF(OR('Досмотр по неделям'!M80="",'Досмотр по неделям'!M80=0),NA(),'Досмотр по неделям'!M80) -> 0.0013625972 | F10: =IF(OR('Досмотр по неделям'!N80="",'Досмотр по неделям'!N80=0),NA(),'Досмотр по неделям'!N80) -> 0.0011979881 | G10: =IF(OR('Досмотр по неделям'!O80="",'Досмотр по неделям'!O80=0),NA(),'Досмотр по неделям'!O80) -> 1.8289895e-05 | H10: =IF(OR('Досмотр по неделям'!P80="",'Досмотр по неделям'!P80=0),NA(),'Досмотр по неделям'!P80) -> 0.0061454047 | J10: Неделя 4 текущего месяца (№) | K10: =IF(K6="","",IF(K6+3>26,"",IF(INDEX('Досмотр по неделям'!$B$73:$B$98,K6+3)<K5,K6+3,""))) -> 8
A11: =TEXT(DAY('Досмотр по неделям'!B81),"00")&"."&TEXT(MONTH('Досмотр по неделям'!B81),"00") -> 31.08 | B11: =IF('Досмотр по неделям'!D81="",NA(),'Досмотр по неделям'!D81) -> #N/A | C11: =IF(OR('Досмотр по неделям'!K81="",'Досмотр по неделям'!K81=0),NA(),'Досмотр по неделям'!K81) -> #N/A | D11: =IF(OR('Досмотр по неделям'!L81="",'Досмотр по неделям'!L81=0),NA(),'Досмотр по неделям'!L81) -> #N/A | E11: =IF(OR('Досмотр по неделям'!M81="",'Досмотр по неделям'!M81=0),NA(),'Досмотр по неделям'!M81) -> #N/A | F11: =IF(OR('Досмотр по неделям'!N81="",'Досмотр по неделям'!N81=0),NA(),'Досмотр по неделям'!N81) -> #N/A | G11: =IF(OR('Досмотр по неделям'!O81="",'Досмотр по неделям'!O81=0),NA(),'Досмотр по неделям'!O81) -> #N/A | H11: =IF(OR('Досмотр по неделям'!P81="",'Досмотр по неделям'!P81=0),NA(),'Досмотр по неделям'!P81) -> #N/A | J11: Неделя 5 текущего месяца (№) | K11: =IF(K6="","",IF(K6+4>26,"",IF(INDEX('Досмотр по неделям'!$B$73:$B$98,K6+4)<K5,K6+4,""))) -> 9
A12: =TEXT(DAY('Досмотр по неделям'!B82),"00")&"."&TEXT(MONTH('Досмотр по неделям'!B82),"00") -> 07.09 | B12: =IF('Досмотр по неделям'!D82="",NA(),'Досмотр по неделям'!D82) -> #N/A | C12: =IF(OR('Досмотр по неделям'!K82="",'Досмотр по неделям'!K82=0),NA(),'Досмотр по неделям'!K82) -> #N/A | D12: =IF(OR('Досмотр по неделям'!L82="",'Досмотр по неделям'!L82=0),NA(),'Досмотр по неделям'!L82) -> #N/A | E12: =IF(OR('Досмотр по неделям'!M82="",'Досмотр по неделям'!M82=0),NA(),'Досмотр по неделям'!M82) -> #N/A | F12: =IF(OR('Досмотр по неделям'!N82="",'Досмотр по неделям'!N82=0),NA(),'Досмотр по неделям'!N82) -> #N/A | G12: =IF(OR('Досмотр по неделям'!O82="",'Досмотр по неделям'!O82=0),NA(),'Досмотр по неделям'!O82) -> #N/A | H12: =IF(OR('Досмотр по неделям'!P82="",'Досмотр по неделям'!P82=0),NA(),'Досмотр по неделям'!P82) -> #N/A
A13: =TEXT(DAY('Досмотр по неделям'!B83),"00")&"."&TEXT(MONTH('Досмотр по неделям'!B83),"00") -> 14.09 | B13: =IF('Досмотр по неделям'!D83="",NA(),'Досмотр по неделям'!D83) -> #N/A | C13: =IF(OR('Досмотр по неделям'!K83="",'Досмотр по неделям'!K83=0),NA(),'Досмотр по неделям'!K83) -> #N/A | D13: =IF(OR('Досмотр по неделям'!L83="",'Досмотр по неделям'!L83=0),NA(),'Досмотр по неделям'!L83) -> #N/A | E13: =IF(OR('Досмотр по неделям'!M83="",'Досмотр по неделям'!M83=0),NA(),'Досмотр по неделям'!M83) -> #N/A | F13: =IF(OR('Досмотр по неделям'!N83="",'Досмотр по неделям'!N83=0),NA(),'Досмотр по неделям'!N83) -> #N/A | G13: =IF(OR('Досмотр по неделям'!O83="",'Досмотр по неделям'!O83=0),NA(),'Досмотр по неделям'!O83) -> #N/A | H13: =IF(OR('Досмотр по неделям'!P83="",'Досмотр по неделям'!P83=0),NA(),'Досмотр по неделям'!P83) -> #N/A
A14: =TEXT(DAY('Досмотр по неделям'!B84),"00")&"."&TEXT(MONTH('Досмотр по неделям'!B84),"00") -> 21.09 | B14: =IF('Досмотр по неделям'!D84="",NA(),'Досмотр по неделям'!D84) -> #N/A | C14: =IF(OR('Досмотр по неделям'!K84="",'Досмотр по неделям'!K84=0),NA(),'Досмотр по неделям'!K84) -> #N/A | D14: =IF(OR('Досмотр по неделям'!L84="",'Досмотр по неделям'!L84=0),NA(),'Досмотр по неделям'!L84) -> #N/A | E14: =IF(OR('Досмотр по неделям'!M84="",'Досмотр по неделям'!M84=0),NA(),'Досмотр по неделям'!M84) -> #N/A | F14: =IF(OR('Досмотр по неделям'!N84="",'Досмотр по неделям'!N84=0),NA(),'Досмотр по неделям'!N84) -> #N/A | G14: =IF(OR('Досмотр по неделям'!O84="",'Досмотр по неделям'!O84=0),NA(),'Досмотр по неделям'!O84) -> #N/A | H14: =IF(OR('Досмотр по неделям'!P84="",'Досмотр по неделям'!P84=0),NA(),'Досмотр по неделям'!P84) -> #N/A
A15: =TEXT(DAY('Досмотр по неделям'!B85),"00")&"."&TEXT(MONTH('Досмотр по неделям'!B85),"00") -> 28.09 | B15: =IF('Досмотр по неделям'!D85="",NA(),'Досмотр по неделям'!D85) -> #N/A | C15: =IF(OR('Досмотр по неделям'!K85="",'Досмотр по неделям'!K85=0),NA(),'Досмотр по неделям'!K85) -> #N/A | D15: =IF(OR('Досмотр по неделям'!L85="",'Досмотр по неделям'!L85=0),NA(),'Досмотр по неделям'!L85) -> #N/A | E15: =IF(OR('Досмотр по неделям'!M85="",'Досмотр по неделям'!M85=0),NA(),'Досмотр по неделям'!M85) -> #N/A | F15: =IF(OR('Досмотр по неделям'!N85="",'Досмотр по неделям'!N85=0),NA(),'Досмотр по неделям'!N85) -> #N/A | G15: =IF(OR('Досмотр по неделям'!O85="",'Досмотр по неделям'!O85=0),NA(),'Досмотр по неделям'!O85) -> #N/A | H15: =IF(OR('Досмотр по неделям'!P85="",'Досмотр по неделям'!P85=0),NA(),'Досмотр по неделям'!P85) -> #N/A
A16: =TEXT(DAY('Досмотр по неделям'!B86),"00")&"."&TEXT(MONTH('Досмотр по неделям'!B86),"00") -> 05.10 | B16: =IF('Досмотр по неделям'!D86="",NA(),'Досмотр по неделям'!D86) -> #N/A | C16: =IF(OR('Досмотр по неделям'!K86="",'Досмотр по неделям'!K86=0),NA(),'Досмотр по неделям'!K86) -> #N/A | D16: =IF(OR('Досмотр по неделям'!L86="",'Досмотр по неделям'!L86=0),NA(),'Досмотр по неделям'!L86) -> #N/A | E16: =IF(OR('Досмотр по неделям'!M86="",'Досмотр по неделям'!M86=0),NA(),'Досмотр по неделям'!M86) -> #N/A | F16: =IF(OR('Досмотр по неделям'!N86="",'Досмотр по неделям'!N86=0),NA(),'Досмотр по неделям'!N86) -> #N/A | G16: =IF(OR('Досмотр по неделям'!O86="",'Досмотр по неделям'!O86=0),NA(),'Досмотр по неделям'!O86) -> #N/A | H16: =IF(OR('Досмотр по неделям'!P86="",'Досмотр по неделям'!P86=0),NA(),'Досмотр по неделям'!P86) -> #N/A
A17: =TEXT(DAY('Досмотр по неделям'!B87),"00")&"."&TEXT(MONTH('Досмотр по неделям'!B87),"00") -> 12.10 | B17: =IF('Досмотр по неделям'!D87="",NA(),'Досмотр по неделям'!D87) -> #N/A | C17: =IF(OR('Досмотр по неделям'!K87="",'Досмотр по неделям'!K87=0),NA(),'Досмотр по неделям'!K87) -> #N/A | D17: =IF(OR('Досмотр по неделям'!L87="",'Досмотр по неделям'!L87=0),NA(),'Досмотр по неделям'!L87) -> #N/A | E17: =IF(OR('Досмотр по неделям'!M87="",'Досмотр по неделям'!M87=0),NA(),'Досмотр по неделям'!M87) -> #N/A | F17: =IF(OR('Досмотр по неделям'!N87="",'Досмотр по неделям'!N87=0),NA(),'Досмотр по неделям'!N87) -> #N/A | G17: =IF(OR('Досмотр по неделям'!O87="",'Досмотр по неделям'!O87=0),NA(),'Досмотр по неделям'!O87) -> #N/A | H17: =IF(OR('Досмотр по неделям'!P87="",'Досмотр по неделям'!P87=0),NA(),'Досмотр по неделям'!P87) -> #N/A
A18: =TEXT(DAY('Досмотр по неделям'!B88),"00")&"."&TEXT(MONTH('Досмотр по неделям'!B88),"00") -> 19.10 | B18: =IF('Досмотр по неделям'!D88="",NA(),'Досмотр по неделям'!D88) -> #N/A | C18: =IF(OR('Досмотр по неделям'!K88="",'Досмотр по неделям'!K88=0),NA(),'Досмотр по неделям'!K88) -> #N/A | D18: =IF(OR('Досмотр по неделям'!L88="",'Досмотр по неделям'!L88=0),NA(),'Досмотр по неделям'!L88) -> #N/A | E18: =IF(OR('Досмотр по неделям'!M88="",'Досмотр по неделям'!M88=0),NA(),'Досмотр по неделям'!M88) -> #N/A | F18: =IF(OR('Досмотр по неделям'!N88="",'Досмотр по неделям'!N88=0),NA(),'Досмотр по неделям'!N88) -> #N/A | G18: =IF(OR('Досмотр по неделям'!O88="",'Досмотр по неделям'!O88=0),NA(),'Досмотр по неделям'!O88) -> #N/A | H18: =IF(OR('Досмотр по неделям'!P88="",'Досмотр по неделям'!P88=0),NA(),'Досмотр по неделям'!P88) -> #N/A
A19: =TEXT(DAY('Досмотр по неделям'!B89),"00")&"."&TEXT(MONTH('Досмотр по неделям'!B89),"00") -> 26.10 | B19: =IF('Досмотр по неделям'!D89="",NA(),'Досмотр по неделям'!D89) -> #N/A | C19: =IF(OR('Досмотр по неделям'!K89="",'Досмотр по неделям'!K89=0),NA(),'Досмотр по неделям'!K89) -> #N/A | D19: =IF(OR('Досмотр по неделям'!L89="",'Досмотр по неделям'!L89=0),NA(),'Досмотр по неделям'!L89) -> #N/A | E19: =IF(OR('Досмотр по неделям'!M89="",'Досмотр по неделям'!M89=0),NA(),'Досмотр по неделям'!M89) -> #N/A | F19: =IF(OR('Досмотр по неделям'!N89="",'Досмотр по неделям'!N89=0),NA(),'Досмотр по неделям'!N89) -> #N/A | G19: =IF(OR('Досмотр по неделям'!O89="",'Досмотр по неделям'!O89=0),NA(),'Досмотр по неделям'!O89) -> #N/A | H19: =IF(OR('Досмотр по неделям'!P89="",'Досмотр по неделям'!P89=0),NA(),'Досмотр по неделям'!P89) -> #N/A
A20: =TEXT(DAY('Досмотр по неделям'!B90),"00")&"."&TEXT(MONTH('Досмотр по неделям'!B90),"00") -> 02.11 | B20: =IF('Досмотр по неделям'!D90="",NA(),'Досмотр по неделям'!D90) -> #N/A | C20: =IF(OR('Досмотр по неделям'!K90="",'Досмотр по неделям'!K90=0),NA(),'Досмотр по неделям'!K90) -> #N/A | D20: =IF(OR('Досмотр по неделям'!L90="",'Досмотр по неделям'!L90=0),NA(),'Досмотр по неделям'!L90) -> #N/A | E20: =IF(OR('Досмотр по неделям'!M90="",'Досмотр по неделям'!M90=0),NA(),'Досмотр по неделям'!M90) -> #N/A | F20: =IF(OR('Досмотр по неделям'!N90="",'Досмотр по неделям'!N90=0),NA(),'Досмотр по неделям'!N90) -> #N/A | G20: =IF(OR('Досмотр по неделям'!O90="",'Досмотр по неделям'!O90=0),NA(),'Досмотр по неделям'!O90) -> #N/A | H20: =IF(OR('Досмотр по неделям'!P90="",'Досмотр по неделям'!P90=0),NA(),'Досмотр по неделям'!P90) -> #N/A
A21: =TEXT(DAY('Досмотр по неделям'!B91),"00")&"."&TEXT(MONTH('Досмотр по неделям'!B91),"00") -> 09.11 | B21: =IF('Досмотр по неделям'!D91="",NA(),'Досмотр по неделям'!D91) -> #N/A | C21: =IF(OR('Досмотр по неделям'!K91="",'Досмотр по неделям'!K91=0),NA(),'Досмотр по неделям'!K91) -> #N/A | D21: =IF(OR('Досмотр по неделям'!L91="",'Досмотр по неделям'!L91=0),NA(),'Досмотр по неделям'!L91) -> #N/A | E21: =IF(OR('Досмотр по неделям'!M91="",'Досмотр по неделям'!M91=0),NA(),'Досмотр по неделям'!M91) -> #N/A | F21: =IF(OR('Досмотр по неделям'!N91="",'Досмотр по неделям'!N91=0),NA(),'Досмотр по неделям'!N91) -> #N/A | G21: =IF(OR('Досмотр по неделям'!O91="",'Досмотр по неделям'!O91=0),NA(),'Досмотр по неделям'!O91) -> #N/A | H21: =IF(OR('Досмотр по неделям'!P91="",'Досмотр по неделям'!P91=0),NA(),'Досмотр по неделям'!P91) -> #N/A
A22: =TEXT(DAY('Досмотр по неделям'!B92),"00")&"."&TEXT(MONTH('Досмотр по неделям'!B92),"00") -> 16.11 | B22: =IF('Досмотр по неделям'!D92="",NA(),'Досмотр по неделям'!D92) -> #N/A | C22: =IF(OR('Досмотр по неделям'!K92="",'Досмотр по неделям'!K92=0),NA(),'Досмотр по неделям'!K92) -> #N/A | D22: =IF(OR('Досмотр по неделям'!L92="",'Досмотр по неделям'!L92=0),NA(),'Досмотр по неделям'!L92) -> #N/A | E22: =IF(OR('Досмотр по неделям'!M92="",'Досмотр по неделям'!M92=0),NA(),'Досмотр по неделям'!M92) -> #N/A | F22: =IF(OR('Досмотр по неделям'!N92="",'Досмотр по неделям'!N92=0),NA(),'Досмотр по неделям'!N92) -> #N/A | G22: =IF(OR('Досмотр по неделям'!O92="",'Досмотр по неделям'!O92=0),NA(),'Досмотр по неделям'!O92) -> #N/A | H22: =IF(OR('Досмотр по неделям'!P92="",'Досмотр по неделям'!P92=0),NA(),'Досмотр по неделям'!P92) -> #N/A
A23: =TEXT(DAY('Досмотр по неделям'!B93),"00")&"."&TEXT(MONTH('Досмотр по неделям'!B93),"00") -> 23.11 | B23: =IF('Досмотр по неделям'!D93="",NA(),'Досмотр по неделям'!D93) -> #N/A | C23: =IF(OR('Досмотр по неделям'!K93="",'Досмотр по неделям'!K93=0),NA(),'Досмотр по неделям'!K93) -> #N/A | D23: =IF(OR('Досмотр по неделям'!L93="",'Досмотр по неделям'!L93=0),NA(),'Досмотр по неделям'!L93) -> #N/A | E23: =IF(OR('Досмотр по неделям'!M93="",'Досмотр по неделям'!M93=0),NA(),'Досмотр по неделям'!M93) -> #N/A | F23: =IF(OR('Досмотр по неделям'!N93="",'Досмотр по неделям'!N93=0),NA(),'Досмотр по неделям'!N93) -> #N/A | G23: =IF(OR('Досмотр по неделям'!O93="",'Досмотр по неделям'!O93=0),NA(),'Досмотр по неделям'!O93) -> #N/A | H23: =IF(OR('Досмотр по неделям'!P93="",'Досмотр по неделям'!P93=0),NA(),'Досмотр по неделям'!P93) -> #N/A
... A28: =TEXT(DAY('Досмотр по неделям'!B98),"00")&"."&TEXT(MONTH('Досмотр по неделям'!B98),"00") -> 28.12 | B28: =IF('Досмотр по неделям'!D98="",NA(),'Досмотр по неделям'!D98) -> #N/A | C28: =IF(OR('Досмотр по неделям'!K98="",'Досмотр по неделям'!K98=0),NA(),'Досмотр по неделям'!K98) -> #N/A | D28: =IF(OR('Досмотр по неделям'!L98="",'Досмотр по неделям'!L98=0),NA(),'Досмотр по неделям'!L98) -> #N/A | E28: =IF(OR('Досмотр по неделям'!M98="",'Досмотр по неделям'!M98=0),NA(),'Досмотр по неделям'!M98) -> #N/A | F28: =IF(OR('Досмотр по неделям'!N98="",'Досмотр по неделям'!N98=0),NA(),'Досмотр по неделям'!N98) -> #N/A | G28: =IF(OR('Досмотр по неделям'!O98="",'Досмотр по неделям'!O98=0),NA(),'Досмотр по неделям'!O98) -> #N/A | H28: =IF(OR('Досмотр по неделям'!P98="",'Досмотр по неделям'!P98=0),NA(),'Досмотр по неделям'!P98) -> #N/A
